<robot name="myCar">
    <!-- set base_footprint  -->
    <link name="base_footprint">
        <visual>
            <geometry>
                <sphere radius="0.001" />
            </geometry>
        </visual>
    </link>

    <!-- Add chassis -->
    <!-- 
        shape: cylinder
        radius: 0.1m
        length: 0.08m
     -->
    <link name="base_link">
        <visual>
            <geometry>
                <cylinder radius="0.1" length="0.08" />
            </geometry>
            <origin xyz="0 0 0" rpy="0 0 0" />
            <material name="yellow">
                <color rgba="0.8 0.5 0 0.5" />
            </material>
        </visual>
    </link>

    <!-- Add drive wheel -->
    <!-- 
        shape: cyliner
        radius: 0.035
        length: 0.015
     -->
    <link name="left_drive_wheel">
        <visual>
            <geometry>
                <cylinder radius="0.0325" length="0.015" />
            </geometry>
            <origin xyz="0 0 0" rpy="1.5708 0 0" />
            <material name="black">
                <color rgba="0 0 0 1" />
            </material>
        </visual>
    </link>   
    <link name="right_drive_wheel">
        <visual>
            <geometry>
                <cylinder radius="0.035" length="0.015" />
            </geometry>
            <origin xyz="0 0 0" rpy="1.5708 0 0" />
            <material name="black">
                <color rgba="0 0 0 1" />
            </material>
        </visual>
    </link>

    <!-- Add Cardan wheel -->
    <!-- 
        shape: ball
        radius: 0.0075m
     -->
    <link name="front_cardan_ball">
        <visual>
            <geometry>
                <sphere radius="0.0075" />
            </geometry>
            <origin xyz="0 0 0" rpy="0 0 0" />
            <material name="black">
                <color rgba="0 0 0 1" />
            </material>
        </visual>
    </link>
    <link name="back_cardan_ball">
        <visual>
            <geometry>
                <sphere radius="0.0075" />
            </geometry>
            <origin xyz="0 0 0" rpy="0 0 0" />
            <material name="black">
                <color rgba="0 0 0 1" />
            </material>
        </visual>
    </link>


    <!-- joint -->
    <!-- joint  base_footprint and base_link-->
    <!-- 
        chassis height 0.015m
        z = length/2 + 0.015
     -->
    <joint name="base_link2base_footprint" type="fixed">
        <parent link="base_footprint" />
        <child link="base_link" />
        <origin xyz="0 0 0.055" />
    </joint>

    <!-- joint base_link and whell -->
    <!-- 
        left
        x= 0
        y=0.1
        z=0.055-0.0325=0.0225
     -->
    <joint name="left_drive_wheel2base_link" type="continuous">
        <parent link="base_link" />
        <child link="left_drive_wheel" />
        <origin xyz="0 0.1 -0.0225" />
        <axis xyz="0 1 0" />
    </joint>
    <joint name="right_drive_wheel2base_link" type="continuous">
        <parent link="base_link" />
        <child link="right_drive_wheel" />
        <origin xyz="0 -0.1 -0.0225" />
        <axis xyz="0 1 0" />
    </joint>

    <!-- joint base_link and whell -->
    <!-- 
        left
        x= 0.08
        y= 0
        z=0.055-0.0075=0.0475
     -->
    <joint name="front_cardan_ball2base_link" type="continuous">
        <parent link="base_link" />
        <child link="front_cardan_ball" />
        <origin xyz="0.08 0 -0.0475" />
        <axis xyz="0 1 0" />
    </joint>
    <joint name="back_cardan_ball2base_link" type="continuous">
        <parent link="base_link" />
        <child link="back_cardan_ball" />
        <origin xyz="-0.08 0 -0.0475" />
        <axis xyz="0 1 0" />
    </joint>

</robot>
   

